[2023-08-03T15:13:47.704+0000] {taskinstance.py:1103} INFO - Dependencies all met for dep_context=non-requeueable deps ti=<TaskInstance: adx_generate_auction.generate_auction2 manual__2023-08-03T15:13:45.934224+00:00 [queued]>
[2023-08-03T15:13:47.718+0000] {taskinstance.py:1103} INFO - Dependencies all met for dep_context=requeueable deps ti=<TaskInstance: adx_generate_auction.generate_auction2 manual__2023-08-03T15:13:45.934224+00:00 [queued]>
[2023-08-03T15:13:47.720+0000] {taskinstance.py:1308} INFO - Starting attempt 1 of 1
[2023-08-03T15:13:47.741+0000] {taskinstance.py:1327} INFO - Executing <Task(_PythonDecoratedOperator): generate_auction2> on 2023-08-03 15:13:45.934224+00:00
[2023-08-03T15:13:47.751+0000] {standard_task_runner.py:57} INFO - Started process 187 to run task
[2023-08-03T15:13:47.757+0000] {standard_task_runner.py:84} INFO - Running: ['***', 'tasks', 'run', 'adx_generate_auction', 'generate_auction2', 'manual__2023-08-03T15:13:45.934224+00:00', '--job-id', '3', '--raw', '--subdir', 'DAGS_FOLDER/template/adx-generate_auction.py', '--cfg-path', '/tmp/tmpt7ifqu92']
[2023-08-03T15:13:47.763+0000] {standard_task_runner.py:85} INFO - Job 3: Subtask generate_auction2
[2023-08-03T15:13:47.835+0000] {task_command.py:410} INFO - Running <TaskInstance: adx_generate_auction.generate_auction2 manual__2023-08-03T15:13:45.934224+00:00 [running]> on host c20bc3743684
[2023-08-03T15:13:47.912+0000] {taskinstance.py:1547} INFO - Exporting env vars: AIRFLOW_CTX_DAG_OWNER='***' AIRFLOW_CTX_DAG_ID='adx_generate_auction' AIRFLOW_CTX_TASK_ID='generate_auction2' AIRFLOW_CTX_EXECUTION_DATE='2023-08-03T15:13:45.934224+00:00' AIRFLOW_CTX_TRY_NUMBER='1' AIRFLOW_CTX_DAG_RUN_ID='manual__2023-08-03T15:13:45.934224+00:00'
[2023-08-03T15:13:47.918+0000] {taskinstance.py:1824} ERROR - Task failed with exception
Traceback (most recent call last):
  File "/home/airflow/.local/lib/python3.7/site-packages/airflow/decorators/base.py", line 220, in execute
    return_value = super().execute(context)
  File "/home/airflow/.local/lib/python3.7/site-packages/airflow/operators/python.py", line 181, in execute
    return_value = self.execute_callable()
  File "/home/airflow/.local/lib/python3.7/site-packages/airflow/operators/python.py", line 198, in execute_callable
    return self.python_callable(*self.op_args, **self.op_kwargs)
  File "/opt/airflow/dags/template/adx-generate_auction.py", line 35, in generate_auction2
    shutil.copyfile(config_filepath + "/template/adx-auction.py", new_filename)
  File "/usr/local/lib/python3.7/shutil.py", line 120, in copyfile
    with open(src, 'rb') as fsrc:
FileNotFoundError: [Errno 2] No such file or directory: '/opt/airflow/dags/template/template/adx-auction.py'
[2023-08-03T15:13:47.930+0000] {taskinstance.py:1350} INFO - Marking task as FAILED. dag_id=adx_generate_auction, task_id=generate_auction2, execution_date=20230803T151345, start_date=20230803T151347, end_date=20230803T151347
[2023-08-03T15:13:47.940+0000] {standard_task_runner.py:109} ERROR - Failed to execute job 3 for task generate_auction2 ([Errno 2] No such file or directory: '/opt/airflow/dags/template/template/adx-auction.py'; 187)
[2023-08-03T15:13:47.971+0000] {local_task_job_runner.py:225} INFO - Task exited with return code 1
[2023-08-03T15:13:47.989+0000] {taskinstance.py:2653} INFO - 0 downstream tasks scheduled from follow-on schedule check
